<?xml version="1.0" ?>
<robot xmlns:xacro="http://ros.org/wiki/xacro">

<!-- finger_length: Length of finger from gripper base. (was 0.023) -->
<!-- finger_tip:    Offset of finger tip along fingers' motion direction.
                    Use e.g. for single contact point tip on finger. (default 0) -->
<xacro:macro name="wsg_50_xacro" params="name finger_length finger_tip">

<!-- BASE LINK -->
 <link name="${name}_base_link">
      <visual>
         <origin xyz="0.0 0 0" rpy="0 0 0" />
         <geometry>
            <mesh filename="package://wsg50_gripper/meshes/WSG50_110.stl" scale="1 1 1"/>
         </geometry>
         <material name="grey">
            <color rgba="0.5 0.5 0.5 1"/>
         </material>
      </visual>

      <collision>
          <origin xyz="0.0 0 0" rpy="0 0 0" />
          <geometry>
             <mesh filename="package://wsg50_gripper/meshes/WSG50_110.stl" scale="1 1 1"/>
         </geometry>
     </collision>
  </link>

  <joint name="${name}_center_joint" type="fixed">
     <origin xyz="0 0 ${finger_length}" rpy="0 0 0" />      <!--origin xyz="-0.0067 0 0.049" rpy="0 0 0" /-->
     <parent link="${name}_base_link"/>
     <child link="${name}_center" />
  </joint>


  <link name="${name}_center">
  </link>

  <!-- GRIPPER LEFT -->
  <joint name="${name}_finger_left_joint" type="prismatic">
     <limit lower="-0.055" upper="-0.0027" effort="1.0" velocity="1.0"/>
     <origin xyz="0 0 0" rpy="0 0 0" />
     <parent link="${name}_base_link"/>
     <child link="${name}_gripper_left" />
     <!--dynamics damping="0.5" /-->
     <axis xyz="1 0 0"/>
  </joint>

  <!--joint name="${name}_finger_left_joint" type="fixed">      
     <origin xyz="0 0 0" rpy="0 0 0" />
     <parent link="${name}_base_link"/>
     <child link="${name}_gripper_left" />
  </joint-->

  <link name="${name}_gripper_left">
      <visual>
          <origin xyz="0.0 0 0" rpy="0 0 0" />
          <geometry>
             <mesh filename="package://wsg50_gripper/meshes/GUIDE_WSG50_110.stl" scale="0.001 0.001 0.001"/>
	     <!--box size="0.0175 0.03 0.024"/-->
          </geometry>
          <material name="blue">
		      <color rgba="0 0 1 1"/>
      	  </material>
      </visual>

      <collision>
          <origin xyz="0 0 0" rpy="0 0 0" />
          <geometry>
	     <!--box size="0.0175 0.03 0.024"/-->
             <mesh filename="package://wsg50_gripper/meshes/GUIDE_WSG50_110.stl" scale="0.001 0.001 0.001"/>
         </geometry>
     </collision>
  </link>

  <!-- LEFT FINGER -->
  <joint name="${name}_guide_joint_finger_left" type="fixed">
     <origin xyz="0 0 0" rpy="0 0 0" />
     <parent link="${name}_gripper_left"/>
     <child link="${name}_finger_left" />
     <axis xyz="1 0 0"/>
     <limit effort="100" velocity="100"/>
  </joint>

  <link name="${name}_finger_left">
      <visual>
	      <origin xyz="0.0 0 0" rpy="0 0 0" />
         <geometry>
            <!--mesh filename="package://wsg_50_simulation/meshes/WSG-FMF.stl" scale="0.001 0.001 0.001"/-->
            <mesh filename="package://wsg50_gripper/meshes/REMODEL_finger.stl" scale="1 1 1"/>
         </geometry>
         <material name="black">
            <color rgba="0 0 0 1"/>
         </material>
      </visual>

      <collision>
          <!--origin xyz="0 0 0.1" rpy="0 0 0" /-->
	      <origin xyz="0 0 0" rpy="0 0 0" />
         <geometry>
            <!--<mesh filename="package://wsg_50_simulation/meshes/WSG-FMF.stl" scale="0.001 0.001 0.001"/>-->
	         <mesh filename="package://wsg50_gripper/meshes/REMODEL_finger.stl" scale="1 1 1"/>
         </geometry>
     </collision>
  </link>

  <!-- GRIPPER RIGHT -->
  <joint name="${name}_finger_right_joint" type="prismatic">
     <limit lower="0.0027" upper="0.055" effort="1.0" velocity="1.0"/>
     <origin xyz="0 0 0" rpy="0 0 3.14159" />
     <parent link="${name}_base_link"/>
     <child link="${name}_gripper_right" />
     <axis xyz="-1 0 0"/>
     <!--dynamics damping="0.7" friction="0.7"/-->
     <mimic joint="${name}_finger_left_joint" multiplier="-1.0" offset="0.0"/>
     <!--dynamics damping="0.5" /-->
  </joint>
  <!--joint name="${name}_finger_right_joint" type="fixed">
     <origin xyz="0 0 0" rpy="0 0 3.14159" />
     <parent link="${name}_base_link"/>
     <child link="${name}_gripper_right" />
  </joint-->
	
   <link name="${name}_gripper_right">
      <visual>
         <origin xyz="0.0 0 0" rpy="0 0 0" />
         <geometry>
            <mesh filename="package://wsg50_gripper/meshes/GUIDE_WSG50_110.stl" scale="0.001 0.001 0.001"/>
	         <!--box size="0.0175 0.03 0.024"/-->
         </geometry>
         <material name="blue">
		      <color rgba="0 0 1 1"/>
         </material>
      </visual>

      <collision>
         <origin xyz="0 0 0" rpy="0 0 0" />
         <geometry>
            <!--box size="0.0175 0.03 0.024"/-->
            <mesh filename="package://wsg50_gripper/meshes/GUIDE_WSG50_110.stl" scale="0.001 0.001 0.001"/>
         </geometry>
      </collision>
   </link>

  <!-- RIGHT FINGER -->

  <joint name="${name}_guide_joint_finger_right" type="fixed">
     <origin xyz="0 0 0" rpy="0 0 0" />
     <parent link="${name}_gripper_right"/>
     <child link="${name}_finger_right" />
     <axis xyz="1 0 0"/>
     <limit effort="100" velocity="100"/>
  </joint>

  <link name="${name}_finger_right">
      <visual>
         <!--origin xyz="0.0 0 0.1" rpy="0 0 0" /-->
	      <origin xyz="0.0 0 0" rpy="0 0 0" />
         <geometry>
            <!--mesh filename="package://wsg_50_simulation/meshes/WSG-FMF.stl" scale="0.001 0.001 0.001"/-->
            <mesh filename="package://wsg50_gripper/meshes/REMODEL_finger.stl" scale="1 1 1"/>
         </geometry>
         <material name="black">
		      <color rgba="0 0 0 1"/>
         </material>
      </visual>

      <collision>
         <!--origin xyz="0 0 0.1" rpy="0 0 0" /-->
         <origin xyz="0 0 0" rpy="0 0 0" />
         <geometry>
            <!--mesh filename="package://wsg_50_simulation/meshes/WSG-FMF.stl" scale="0.001 0.001 0.001"/-->
	         <mesh filename="package://wsg50_gripper/meshes/REMODEL_finger.stl" scale="1 1 1"/>
         </geometry>
     </collision>
  </link>

</xacro:macro>

</robot>

